Workbook
Name DayaBeda: [1]process02!$BF$74:$DC$77
Name Kesimpulan: [1]process02!$BE$84:$DC$88
Name PolaJawaban01: [1]process02!$E$91:$BC$97

Sheet Input01
A4: (Hanya diperkenankan mengisi data atau menghapus tetapi tidak boleh memindah isi data atau menggunakan fasilitas Cut Paste)
A6: Keterangan | B6: Kolom Pengisian | C6: Validasi
A7: Satuan Pendidikan | B7: MA Salafiyah Bantarsari | C7: =IF(B7="","Belum Diisi","OK") -> OK
A8: Mata Pelajaran | B8: Informatika | C8: =IF(B8="","Belum Diisi","OK") -> OK
A9: Kelas/Program | B9: Fase F XI 5 | C9: =IF(B9="","Belum Diisi","OK") -> OK
A10: Nama Tes | B10: Asesmen Sumatif Tengah Semester (ASTS) | C10: =IF(B10="","Belum Diisi","OK") -> OK
A11: Pokok Bahasan/Sub | B11: Bab 1, 2 | C11: =IF(B11="","Belum Diisi","OK") -> OK
A12: Nama Guru | B12: Abdul Mu'iz | C12: =IF(B12="","Belum Diisi","OK") -> OK
A13: NIP | B13: - | C13: =IF(B13="","Belum Diisi","OK") -> OK
A14: Semester | B14: Ganjil | C14: =IF(B14="","Belum Diisi","OK") -> OK
A15: Tahun Pelajaran | B15: 2026/2027 | C15: =IF(B15="","Belum Diisi","OK") -> OK
A16: Tanggal Tes | B16: 23 September 2026 | C16: =IF(B16="","Belum Diisi","OK") -> OK
A17: Tanggal Diperiksa | B17: 1 Oktober 2026 | C17: =IF(B17="","Belum Diisi","OK") -> OK
A18: Nama Kepala Sekolah | B18: H. Achmad Chuzin, S.Pd. | C18: =IF(B18="","Belum Diisi","OK") -> OK
... A21: Tanggal Laporan | B21: 15 Oktober 2026 | C21: =IF(B21="","Belum Diisi","OK") -> OK
A22: Skala Penilaian (4, 10 atau 100) | B22: 100 | C22: =IF(B22="","Belum Diisi",IF(OR(B22=100,B22=10,B22=4),"OK","Salah pengisian")) -> OK
A23: Nilai KKM | B23: 67 | C23: =IF(B23>B22,"Salah Pengisian",IF(B23="","Belum Diisi","OK")) -> OK
A25: Jumlah dan Bobot Soal
A26: Jumlah soal pilihan ganda (Max 50) | B26: 35 | C26: =IF(B26="","Belum Diisi",IF(AND(B26>0,B26<=50),"OK","Salah pengisian")) -> OK
A27: Jumlah soal isian singkat (Max 20) | B27: 5 | C27: =IF(B27="","Belum Diisi",IF(AND(B27>0,B27<=20),"OK","Salah pengisian")) -> OK
A28: Jumlah soal essay (Max 10) | C28: =IF(B28="","Belum Diisi",IF(AND(B28>0,B28<=10),"OK","Salah pengisian")) -> Belum Diisi
A29: Bobot soal pilihan ganda | B29: 1 | C29: =IF(B26=0,"Tidak perlu diisi",IF(AND(B26=0,B29=""),"OK",IF(B29="","Belum diisi",IF((SUM($B$29:$B$31))<>1,"Jumlah bobot tidak sama dengan 100",IF(AND(B29>0,B29<=100),"OK","Salah pengisian"))))) -> Jumlah bobot tidak sama dengan 100
A30: Bobot soal isian singkat | B30: 1 | C30: =IF(B27=0,"Tidak perlu diisi",IF(AND(B27=0,B30=""),"OK",IF(B30="","Belum diisi",IF((SUM($B$29:$B$31))<>1,"Jumlah bobot tidak sama dengan 100",IF(AND(B30>0,B30<=100),"OK","Salah pengisian"))))) -> Jumlah bobot tidak sama dengan 100
A31: Bobot soal essay | C31: =IF(B28=0,"Tidak perlu diisi",IF(AND(B28=0,B31=""),"OK",IF(B31="","Belum diisi",IF((SUM($B$29:$B$31))<>1,"Jumlah bobot tidak sama dengan 100",IF(AND(B31>0,B31<=100),"OK","Salah pengisian"))))) -> Tidak perlu diisi
A33: Data Soal Pilihan Ganda dan Isian Singkat
A34: Jumlah Alternatif Jawaban (Max 5) | B34: 5 | C34: =IF(B34="","Belum Diisi",IF(B34<=5,"OK","Salah")) -> OK
A35: Skor Benar Soal Objektif | B35: 2 | C35: =IF(B35="","Belum Diisi",IF(B35>0,"OK","Salah pengisian")) -> OK
A36: Skor Salah soal objektif | B36: 0 | C36: =IF(B36<=0,"OK","Salah pengisian") -> OK
A37: Kunci Jawaban (Max 50 soal) | B37: ADCEECBDACCDEAAEDBCBDEDECADCEECBBBB | C37: =IF(B37="","Belum Diisi",IF(LEN(B37)>B26,"Kunci jawaban lebih",IF(LEN(B37)<B26,"Kunci jawaban kurang","OK"))) -> OK
A38: Kemampuan yang Diukur untuk Soal Pilihan Ganda
A39: Soal Nomor 1 | B39: 1 | C39: =IF(LEN($B$37)<VALUE(RIGHT(A39,2)),"Tidak Perlu Diisi",IF(AND(LEN($B$37)>=VALUE(RIGHT(A39,2)),B39<>""),"OK","Belum Diisi")) -> OK
A40: Soal Nomor 2 | B40: 2 | C40: =IF(LEN($B$37)<VALUE(RIGHT(A40,2)),"Tidak Perlu Diisi",IF(AND(LEN($B$37)>=VALUE(RIGHT(A40,2)),B40<>""),"OK","Belum Diisi")) -> OK
A41: Soal Nomor 3 | B41: 3 | C41: =IF(LEN($B$37)<VALUE(RIGHT(A41,2)),"Tidak Perlu Diisi",IF(AND(LEN($B$37)>=VALUE(RIGHT(A41,2)),B41<>""),"OK","Belum Diisi")) -> OK
A42: Soal Nomor 4 | B42: 4 | C42: =IF(LEN($B$37)<VALUE(RIGHT(A42,2)),"Tidak Perlu Diisi",IF(AND(LEN($B$37)>=VALUE(RIGHT(A42,2)),B42<>""),"OK","Belum Diisi")) -> OK
A43: Soal Nomor 5 | B43: 5 | C43: =IF(LEN($B$37)<VALUE(RIGHT(A43,2)),"Tidak Perlu Diisi",IF(AND(LEN($B$37)>=VALUE(RIGHT(A43,2)),B43<>""),"OK","Belum Diisi")) -> OK
A44: Soal Nomor 6 | B44: 6 | C44: =IF(LEN($B$37)<VALUE(RIGHT(A44,2)),"Tidak Perlu Diisi",IF(AND(LEN($B$37)>=VALUE(RIGHT(A44,2)),B44<>""),"OK","Belum Diisi")) -> OK
A45: Soal Nomor 7 | B45: 7 | C45: =IF(LEN($B$37)<VALUE(RIGHT(A45,2)),"Tidak Perlu Diisi",IF(AND(LEN($B$37)>=VALUE(RIGHT(A45,2)),B45<>""),"OK","Belum Diisi")) -> OK
A46: Soal Nomor 8 | B46: 8 | C46: =IF(LEN($B$37)<VALUE(RIGHT(A46,2)),"Tidak Perlu Diisi",IF(AND(LEN($B$37)>=VALUE(RIGHT(A46,2)),B46<>""),"OK","Belum Diisi")) -> OK
A47: Soal Nomor 9 | B47: 9 | C47: =IF(LEN($B$37)<VALUE(RIGHT(A47,2)),"Tidak Perlu Diisi",IF(AND(LEN($B$37)>=VALUE(RIGHT(A47,2)),B47<>""),"OK","Belum Diisi")) -> OK
A48: Soal Nomor 10 | B48: 10 | C48: =IF(LEN($B$37)<VALUE(RIGHT(A48,2)),"Tidak Perlu Diisi",IF(AND(LEN($B$37)>=VALUE(RIGHT(A48,2)),B48<>""),"OK","Belum Diisi")) -> OK
...

Sheet Input02
A1: Identitas dan Jawaban Siswa | CG1: Jangan dihapus
A2: (Hanya diperkenankan mengisi data atau menghapus tetapi tidak boleh memindah isi data atau menggunakan fasilitas Cut Paste) | BV2: Skor Maksimal | CG2: =Input01!B27 -> 5
BV3: =IF(Input01!B111<>"",Input01!B111,"-") -> 4 | BW3: =IF(Input01!B112<>"",Input01!B112,"-") -> 4 | BX3: =IF(Input01!B113<>"",Input01!B113,"-") -> 4 | BY3: =IF(Input01!B114<>"",Input01!B114,"-") -> 4 | BZ3: =IF(Input01!B115<>"",Input01!B115,"-") -> 4 | CA3: =IF(Input01!B116<>"",Input01!B116,"-") -> - | CB3: =IF(Input01!B117<>"",Input01!B117,"-") -> - | CC3: =IF(Input01!B118<>"",Input01!B118,"-") -> - | CD3: =IF(Input01!B119<>"",Input01!B119,"-") -> - | CE3: =IF(Input01!B120<>"",Input01!B120,"-") -> - | CG3: =Input01!B26 -> 35
A4: No | B4: Nama | C4: Jenis Kelamin | D4: Jawaban Siswa Soal Pilihan Ganda | BB4: Skor Jawaban Soal Isian Singkat | BV4: Skor Jawaban Siswa Soal Essay | CG4: Jawaban Siswa Soal Pilihan Ganda (Isikan dengan huruf kapital tanpa spasi, contoh: BCADEABEDCBA)
D5: 1 | E5: 2 | F5: 3 | G5: 4 | H5: 5 | I5: 6 | J5: 7 | K5: 8 | L5: 9 | M5: 10 | N5: 11 | O5: 12 | P5: 13 | Q5: 14 | R5: 15 | S5: 16 | T5: 17 | U5: 18 | V5: 19 | W5: 20 | X5: 21 | Y5: 22 | Z5: 23 | AA5: 24 | AB5: 25 | AC5: 26 | AD5: 27 | AE5: 28 | AF5: 29 | AG5: 30 | AH5: 31 | AI5: 32 | AJ5: 33 | AK5: 34 | AL5: 35 | AM5: 36 | AN5: 37 | AO5: 38 | AP5: 39 | AQ5: 40 | AR5: 41 | AS5: 42 | AT5: 43 | AU5: 44 | AV5: 45 | AW5: 46 | AX5: 47 | AY5: 48 | AZ5: 49 | BA5: 50 | BB5: 1 | BC5: 2 | BD5: 3 | BE5: 4 | BF5: 5 | BG5: 6 | BH5: 7 | BI5: 8 | BJ5: 9 | BK5: 10 | BL5: 11 | BM5: 12 | BN5: 13 | BO5: 14 | BP5: 15 | BQ5: 16 | BR5: 17 | BS5: 18 | BT5: 19 | BU5: 20 | BV5: 1 | BW5: 2 | BX5: 3 | BY5: 4 | BZ5: 5 | CA5: 6 | CB5: 7 | CC5: 8 | CD5: 9 | CE5: 10
A6: 1 | B6: ACHMAD FADILATUL KHANAN | C6: L | D6: D | E6: C | F6: C | G6: E | H6: C | I6: A | J6: D | K6: B | L6: C | M6: B | N6: A | O6: B | P6: C | Q6: D | R6: B | X6: C | Y6: D | Z6: C | AA6: A | AB6: C | BB6: 2 | BC6: 2 | BD6: 2 | BE6: 2 | BF6: 2 | CG6: =D6&E6&F6&G6&H6&I6&J6&K6&L6&M6&N6&O6&P6&Q6&R6&S6&T6&U6&V6&W6&X6&Y6&Z6&AA6&AB6&AC6&AD6&AE6&AF6&AG6&AH6&AI6&AJ6&AK6&AL6&AM6&AN6&AO6&AP6&AQ6&AR6&AS6&AT6&AU6&AV6&AW6&AX6&AY6&AZ6&BA6 -> DCCECADBCBABCDBCDCAC
A7: =A6+1 -> 2 | B7: AFRISA KHOERUNNISA | C7: P | D7: B | E7: B | F7: C | G7: A | H7: B | I7: B | J7: B | K7: C | L7: B | M7: C | N7: C | O7: E | P7: B | Q7: B | R7: C | S7: B | T7: C | U7: C | V7: C | W7: B | X7: B | Y7: B | Z7: B | AA7: B | AB7: C | BB7: 2 | BC7: 2 | BD7: 2 | BE7: 2 | BF7: 2 | CG7: =D7&E7&F7&G7&H7&I7&J7&K7&L7&M7&N7&O7&P7&Q7&R7&S7&T7&U7&V7&W7&X7&Y7&Z7&AA7&AB7&AC7&AD7&AE7&AF7&AG7&AH7&AI7&AJ7&AK7&AL7&AM7&AN7&AO7&AP7&AQ7&AR7&AS7&AT7&AU7&AV7&AW7&AX7&AY7&AZ7&BA7 -> BBCABBBCBCCEBBCBCCCBBBBBC
A8: =A7+1 -> 3 | B8: AHMAD SYAHRIAN RAMADAN | C8: L | CG8: =D8&E8&F8&G8&H8&I8&J8&K8&L8&M8&N8&O8&P8&Q8&R8&S8&T8&U8&V8&W8&X8&Y8&Z8&AA8&AB8&AC8&AD8&AE8&AF8&AG8&AH8&AI8&AJ8&AK8&AL8&AM8&AN8&AO8&AP8&AQ8&AR8&AS8&AT8&AU8&AV8&AW8&AX8&AY8&AZ8&BA8
A9: =A8+1 -> 4 | B9: AHMAD ULUN NUHA | C9: L | CG9: =D9&E9&F9&G9&H9&I9&J9&K9&L9&M9&N9&O9&P9&Q9&R9&S9&T9&U9&V9&W9&X9&Y9&Z9&AA9&AB9&AC9&AD9&AE9&AF9&AG9&AH9&AI9&AJ9&AK9&AL9&AM9&AN9&AO9&AP9&AQ9&AR9&AS9&AT9&AU9&AV9&AW9&AX9&AY9&AZ9&BA9
A10: =A9+1 -> 5 | B10: AHSINUL MUTHORIQ | C10: L | CG10: =D10&E10&F10&G10&H10&I10&J10&K10&L10&M10&N10&O10&P10&Q10&R10&S10&T10&U10&V10&W10&X10&Y10&Z10&AA10&AB10&AC10&AD10&AE10&AF10&AG10&AH10&AI10&AJ10&AK10&AL10&AM10&AN10&AO10&AP10&AQ10&AR10&AS10&AT10&AU10&AV10&AW10&AX10&AY10&AZ10&BA10
A11: =A10+1 -> 6 | B11: ALFIN ARDIANSYAH NAWAWI | C11: L | CG11: =D11&E11&F11&G11&H11&I11&J11&K11&L11&M11&N11&O11&P11&Q11&R11&S11&T11&U11&V11&W11&X11&Y11&Z11&AA11&AB11&AC11&AD11&AE11&AF11&AG11&AH11&AI11&AJ11&AK11&AL11&AM11&AN11&AO11&AP11&AQ11&AR11&AS11&AT11&AU11&AV11&AW11&AX11&AY11&AZ11&BA11
A12: =A11+1 -> 7 | B12: ALIF KHISBULLOH | C12: L | CG12: =D12&E12&F12&G12&H12&I12&J12&K12&L12&M12&N12&O12&P12&Q12&R12&S12&T12&U12&V12&W12&X12&Y12&Z12&AA12&AB12&AC12&AD12&AE12&AF12&AG12&AH12&AI12&AJ12&AK12&AL12&AM12&AN12&AO12&AP12&AQ12&AR12&AS12&AT12&AU12&AV12&AW12&AX12&AY12&AZ12&BA12
A13: =A12+1 -> 8 | B13: AMELLIA AZZAH | C13: P | CG13: =D13&E13&F13&G13&H13&I13&J13&K13&L13&M13&N13&O13&P13&Q13&R13&S13&T13&U13&V13&W13&X13&Y13&Z13&AA13&AB13&AC13&AD13&AE13&AF13&AG13&AH13&AI13&AJ13&AK13&AL13&AM13&AN13&AO13&AP13&AQ13&AR13&AS13&AT13&AU13&AV13&AW13&AX13&AY13&AZ13&BA13
A14: =A13+1 -> 9 | B14: ESTI ZAINAB SA'ADAH | C14: P | CG14: =D14&E14&F14&G14&H14&I14&J14&K14&L14&M14&N14&O14&P14&Q14&R14&S14&T14&U14&V14&W14&X14&Y14&Z14&AA14&AB14&AC14&AD14&AE14&AF14&AG14&AH14&AI14&AJ14&AK14&AL14&AM14&AN14&AO14&AP14&AQ14&AR14&AS14&AT14&AU14&AV14&AW14&AX14&AY14&AZ14&BA14
A15: =A14+1 -> 10 | B15: FILZA MAWADATUN NISA | C15: P | CG15: =D15&E15&F15&G15&H15&I15&J15&K15&L15&M15&N15&O15&P15&Q15&R15&S15&T15&U15&V15&W15&X15&Y15&Z15&AA15&AB15&AC15&AD15&AE15&AF15&AG15&AH15&AI15&AJ15&AK15&AL15&AM15&AN15&AO15&AP15&AQ15&AR15&AS15&AT15&AU15&AV15&AW15&AX15&AY15&AZ15&BA15
A16: =A15+1 -> 11 | B16: HERLINA TASKIA NUFUS | C16: P | CG16: =D16&E16&F16&G16&H16&I16&J16&K16&L16&M16&N16&O16&P16&Q16&R16&S16&T16&U16&V16&W16&X16&Y16&Z16&AA16&AB16&AC16&AD16&AE16&AF16&AG16&AH16&AI16&AJ16&AK16&AL16&AM16&AN16&AO16&AP16&AQ16&AR16&AS16&AT16&AU16&AV16&AW16&AX16&AY16&AZ16&BA16
A17: =A16+1 -> 12 | B17: IRFANGI MAULANA AJRI | C17: L | CG17: =D17&E17&F17&G17&H17&I17&J17&K17&L17&M17&N17&O17&P17&Q17&R17&S17&T17&U17&V17&W17&X17&Y17&Z17&AA17&AB17&AC17&AD17&AE17&AF17&AG17&AH17&AI17&AJ17&AK17&AL17&AM17&AN17&AO17&AP17&AQ17&AR17&AS17&AT17&AU17&AV17&AW17&AX17&AY17&AZ17&BA17
A18: =A17+1 -> 13 | B18: IRMA SURYANINGSIH | C18: P | CG18: =D18&E18&F18&G18&H18&I18&J18&K18&L18&M18&N18&O18&P18&Q18&R18&S18&T18&U18&V18&W18&X18&Y18&Z18&AA18&AB18&AC18&AD18&AE18&AF18&AG18&AH18&AI18&AJ18&AK18&AL18&AM18&AN18&AO18&AP18&AQ18&AR18&AS18&AT18&AU18&AV18&AW18&AX18&AY18&AZ18&BA18
A19: =A18+1 -> 14 | B19: ITA NURROHMAH | C19: P | CG19: =D19&E19&F19&G19&H19&I19&J19&K19&L19&M19&N19&O19&P19&Q19&R19&S19&T19&U19&V19&W19&X19&Y19&Z19&AA19&AB19&AC19&AD19&AE19&AF19&AG19&AH19&AI19&AJ19&AK19&AL19&AM19&AN19&AO19&AP19&AQ19&AR19&AS19&AT19&AU19&AV19&AW19&AX19&AY19&AZ19&BA19
... A35: =A34+1 -> 30 | B35: ZULFIYATUR ROHMAH | C35: P | CG35: =D35&E35&F35&G35&H35&I35&J35&K35&L35&M35&N35&O35&P35&Q35&R35&S35&T35&U35&V35&W35&X35&Y35&Z35&AA35&AB35&AC35&AD35&AE35&AF35&AG35&AH35&AI35&AJ35&AK35&AL35&AM35&AN35&AO35&AP35&AQ35&AR35&AS35&AT35&AU35&AV35&AW35&AX35&AY35&AZ35&BA35
A36: =A35+1 -> 31 | CG36: =D36&E36&F36&G36&H36&I36&J36&K36&L36&M36&N36&O36&P36&Q36&R36&S36&T36&U36&V36&W36&X36&Y36&Z36&AA36&AB36&AC36&AD36&AE36&AF36&AG36&AH36&AI36&AJ36&AK36&AL36&AM36&AN36&AO36&AP36&AQ36&AR36&AS36&AT36&AU36&AV36&AW36&AX36&AY36&AZ36&BA36
A37: =A36+1 -> 32 | CG37: =D37&E37&F37&G37&H37&I37&J37&K37&L37&M37&N37&O37&P37&Q37&R37&S37&T37&U37&V37&W37&X37&Y37&Z37&AA37&AB37&AC37&AD37&AE37&AF37&AG37&AH37&AI37&AJ37&AK37&AL37&AM37&AN37&AO37&AP37&AQ37&AR37&AS37&AT37&AU37&AV37&AW37&AX37&AY37&AZ37&BA37
A38: =A37+1 -> 33 | CG38: =D38&E38&F38&G38&H38&I38&J38&K38&L38&M38&N38&O38&P38&Q38&R38&S38&T38&U38&V38&W38&X38&Y38&Z38&AA38&AB38&AC38&AD38&AE38&AF38&AG38&AH38&AI38&AJ38&AK38&AL38&AM38&AN38&AO38&AP38&AQ38&AR38&AS38&AT38&AU38&AV38&AW38&AX38&AY38&AZ38&BA38
A39: =A38+1 -> 34 | CG39: =D39&E39&F39&G39&H39&I39&J39&K39&L39&M39&N39&O39&P39&Q39&R39&S39&T39&U39&V39&W39&X39&Y39&Z39&AA39&AB39&AC39&AD39&AE39&AF39&AG39&AH39&AI39&AJ39&AK39&AL39&AM39&AN39&AO39&AP39&AQ39&AR39&AS39&AT39&AU39&AV39&AW39&AX39&AY39&AZ39&BA39
A40: =A39+1 -> 35 | CG40: =D40&E40&F40&G40&H40&I40&J40&K40&L40&M40&N40&O40&P40&Q40&R40&S40&T40&U40&V40&W40&X40&Y40&Z40&AA40&AB40&AC40&AD40&AE40&AF40&AG40&AH40&AI40&AJ40&AK40&AL40&AM40&AN40&AO40&AP40&AQ40&AR40&AS40&AT40&AU40&AV40&AW40&AX40&AY40&AZ40&BA40
A41: =A40+1 -> 36 | CG41: =D41&E41&F41&G41&H41&I41&J41&K41&L41&M41&N41&O41&P41&Q41&R41&S41&T41&U41&V41&W41&X41&Y41&Z41&AA41&AB41&AC41&AD41&AE41&AF41&AG41&AH41&AI41&AJ41&AK41&AL41&AM41&AN41&AO41&AP41&AQ41&AR41&AS41&AT41&AU41&AV41&AW41&AX41&AY41&AZ41&BA41
A42: =A41+1 -> 37 | CG42: =D42&E42&F42&G42&H42&I42&J42&K42&L42&M42&N42&O42&P42&Q42&R42&S42&T42&U42&V42&W42&X42&Y42&Z42&AA42&AB42&AC42&AD42&AE42&AF42&AG42&AH42&AI42&AJ42&AK42&AL42&AM42&AN42&AO42&AP42&AQ42&AR42&AS42&AT42&AU42&AV42&AW42&AX42&AY42&AZ42&BA42
A43: =A42+1 -> 38 | CG43: =D43&E43&F43&G43&H43&I43&J43&K43&L43&M43&N43&O43&P43&Q43&R43&S43&T43&U43&V43&W43&X43&Y43&Z43&AA43&AB43&AC43&AD43&AE43&AF43&AG43&AH43&AI43&AJ43&AK43&AL43&AM43&AN43&AO43&AP43&AQ43&AR43&AS43&AT43&AU43&AV43&AW43&AX43&AY43&AZ43&BA43
A44: =A43+1 -> 39 | CG44: =D44&E44&F44&G44&H44&I44&J44&K44&L44&M44&N44&O44&P44&Q44&R44&S44&T44&U44&V44&W44&X44&Y44&Z44&AA44&AB44&AC44&AD44&AE44&AF44&AG44&AH44&AI44&AJ44&AK44&AL44&AM44&AN44&AO44&AP44&AQ44&AR44&AS44&AT44&AU44&AV44&AW44&AX44&AY44&AZ44&BA44
A45: =A44+1 -> 40 | CG45: =D45&E45&F45&G45&H45&I45&J45&K45&L45&M45&N45&O45&P45&Q45&R45&S45&T45&U45&V45&W45&X45&Y45&Z45&AA45&AB45&AC45&AD45&AE45&AF45&AG45&AH45&AI45&AJ45&AK45&AL45&AM45&AN45&AO45&AP45&AQ45&AR45&AS45&AT45&AU45&AV45&AW45&AX45&AY45&AZ45&BA45
A46: =A45+1 -> 41 | CG46: =D46&E46&F46&G46&H46&I46&J46&K46&L46&M46&N46&O46&P46&Q46&R46&S46&T46&U46&V46&W46&X46&Y46&Z46&AA46&AB46&AC46&AD46&AE46&AF46&AG46&AH46&AI46&AJ46&AK46&AL46&AM46&AN46&AO46&AP46&AQ46&AR46&AS46&AT46&AU46&AV46&AW46&AX46&AY46&AZ46&BA46
A47: =A46+1 -> 42 | CG47: =D47&E47&F47&G47&H47&I47&J47&K47&L47&M47&N47&O47&P47&Q47&R47&S47&T47&U47&V47&W47&X47&Y47&Z47&AA47&AB47&AC47&AD47&AE47&AF47&AG47&AH47&AI47&AJ47&AK47&AL47&AM47&AN47&AO47&AP47&AQ47&AR47&AS47&AT47&AU47&AV47&AW47&AX47&AY47&AZ47&BA47
... A205: =A204+1 -> 200 | CG205: =D205&E205&F205&G205&H205&I205&J205&K205&L205&M205&N205&O205&P205&Q205&R205&S205&T205&U205&V205&W205&X205&Y205&Z205&AA205&AB205&AC205&AD205&AE205&AF205&AG205&AH205&AI205&AJ205&AK205&AL205&AM205&AN205&AO205&AP205&AQ205&AR205&AS205&AT205&AU205&AV205&AW205&AX205&AY205&AZ205&BA205

Sheet Data01
A2: Data Jawaban Soal Objektif
A4: Satuan Pendidikan | C4: =": "&Input01!B7 -> : MA Salafiyah Bantarsari
A5: Nama Tes | C5: =": "&Input01!B10 -> : Asesmen Sumatif Tengah Semester (ASTS)
A6: Mata Pelajaran | C6: =": "&Input01!B8 -> : Informatika
A7: Kelas/Program | C7: =": "&Input01!B9 -> : Fase F XI 5
A8: Tanggal Tes | C8: =": "&Input01!B16 -> : 23 September 2026
A9: Nama Guru | C9: =": "&Input01!B12 -> : Abdul Mu'iz
BB10: 50
A11: No | B11: Nama | C11: Jenis Kelamin | D11: Nomor Soal | BB11: Jawaban Siswa Soal Pilihan Ganda (Isikan dengan huruf kapital tanpa spasi, contoh: BCADEABEDCBA)
D12: 1 | E12: 2 | F12: 3 | G12: 4 | H12: 5 | I12: 6 | J12: 7 | K12: 8 | L12: 9 | M12: 10 | N12: 11 | O12: 12 | P12: 13 | Q12: 14 | R12: 15 | S12: 16 | T12: 17 | U12: 18 | V12: 19 | W12: 20 | X12: 21 | Y12: 22 | Z12: 23 | AA12: 24 | AB12: 25 | AC12: 26 | AD12: 27 | AE12: 28 | AF12: 29 | AG12: 30 | AH12: 31 | AI12: 32 | AJ12: 33 | AK12: 34 | AL12: 35 | AM12: 36 | AN12: 37 | AO12: 38 | AP12: 39 | AQ12: 40 | AR12: 41 | AS12: 42 | AT12: 43 | AU12: 44 | AV12: 45 | AW12: 46 | AX12: 47 | AY12: 48 | AZ12: 49 | BA12: 50
A13: -1 | B13: -2 | C13: -3 | D13: -4 | E13: -5 | F13: -6 | G13: -7 | H13: -8 | I13: -9 | J13: -10 | K13: -11 | L13: -12 | M13: -13 | N13: -14 | O13: -15 | P13: -16 | Q13: -17 | R13: -18 | S13: -19 | T13: -20 | U13: -21 | V13: -22 | W13: -23 | X13: -24 | Y13: -25 | Z13: -26 | AA13: -27 | AB13: -28 | AC13: -29 | AD13: -30 | AE13: -31 | AF13: -32 | AG13: -33 | AH13: -34 | AI13: -35 | AJ13: -36 | AK13: -37 | AL13: -38 | AM13: -39 | AN13: -40 | AO13: -41 | AP13: -42 | AQ13: -43 | AR13: -44 | AS13: -45 | AT13: -46 | AU13: -47 | AV13: -48 | AW13: -49 | AX13: -50 | AY13: -51 | AZ13: -52 | BA13: -53 | BB13: -54
A14: =IF(Input02!A6<>"",Input02!A6,"") -> 1 | B14: =IF(Input02!B6<>"",Input02!B6,"") -> ACHMAD FADILATUL KHANAN | C14: =IF(Input02!C6<>"",Input02!C6,"") -> L | D14: =process02!BF17 -> 0 | E14: =process02!BG17 -> 0 | F14: =process02!BH17 -> 1 | G14: =process02!BI17 -> 1 | H14: =process02!BJ17 -> 0 | I14: =process02!BK17 -> 0 | J14: =process02!BL17 -> 0 | K14: =process02!BM17 -> 0 | ... BA14: =process02!DC17 | BB14: =IF(Input02!CG6<>"",Input02!CG6,"") -> DCCECADBCBABCDBCDCAC
A15: =IF(Input02!A7<>"",Input02!A7,"") -> 2 | B15: =IF(Input02!B7<>"",Input02!B7,"") -> AFRISA KHOERUNNISA | C15: =IF(Input02!C7<>"",Input02!C7,"") -> P | D15: =process02!BF18 -> 0 | E15: =process02!BG18 -> 0 | F15: =process02!BH18 -> 1 | G15: =process02!BI18 -> 0 | H15: =process02!BJ18 -> 0 | I15: =process02!BK18 -> 0 | J15: =process02!BL18 -> 1 | K15: =process02!BM18 -> 0 | ... BA15: =process02!DC18 | BB15: =IF(Input02!CG7<>"",Input02!CG7,"") -> BBCABBBCBCCEBBCBCCCBBBBBC
A16: =IF(Input02!A8<>"",Input02!A8,"") -> 3 | B16: =IF(Input02!B8<>"",Input02!B8,"") -> AHMAD SYAHRIAN RAMADAN | C16: =IF(Input02!C8<>"",Input02!C8,"") -> L | D16: =process02!BF19 | E16: =process02!BG19 | F16: =process02!BH19 | G16: =process02!BI19 | H16: =process02!BJ19 | I16: =process02!BK19 | J16: =process02!BL19 | K16: =process02!BM19 | ... BA16: =process02!DC19 | BB16: =IF(Input02!CG8<>"",Input02!CG8,"")
A17: =IF(Input02!A9<>"",Input02!A9,"") -> 4 | B17: =IF(Input02!B9<>"",Input02!B9,"") -> AHMAD ULUN NUHA | C17: =IF(Input02!C9<>"",Input02!C9,"") -> L | D17: =process02!BF20 | E17: =process02!BG20 | F17: =process02!BH20 | G17: =process02!BI20 | H17: =process02!BJ20 | I17: =process02!BK20 | J17: =process02!BL20 | K17: =process02!BM20 | ... BA17: =process02!DC20 | BB17: =IF(Input02!CG9<>"",Input02!CG9,"")
A18: =IF(Input02!A10<>"",Input02!A10,"") -> 5 | B18: =IF(Input02!B10<>"",Input02!B10,"") -> AHSINUL MUTHORIQ | C18: =IF(Input02!C10<>"",Input02!C10,"") -> L | D18: =process02!BF21 | E18: =process02!BG21 | F18: =process02!BH21 | G18: =process02!BI21 | H18: =process02!BJ21 | I18: =process02!BK21 | J18: =process02!BL21 | K18: =process02!BM21 | ... BA18: =process02!DC21 | BB18: =IF(Input02!CG10<>"",Input02!CG10,"")
A19: =IF(Input02!A11<>"",Input02!A11,"") -> 6 | B19: =IF(Input02!B11<>"",Input02!B11,"") -> ALFIN ARDIANSYAH NAWAWI | C19: =IF(Input02!C11<>"",Input02!C11,"") -> L | D19: =process02!BF22 | E19: =process02!BG22 | F19: =process02!BH22 | G19: =process02!BI22 | H19: =process02!BJ22 | I19: =process02!BK22 | J19: =process02!BL22 | K19: =process02!BM22 | ... BA19: =process02!DC22 | BB19: =IF(Input02!CG11<>"",Input02!CG11,"")
A20: =IF(Input02!A12<>"",Input02!A12,"") -> 7 | B20: =IF(Input02!B12<>"",Input02!B12,"") -> ALIF KHISBULLOH | C20: =IF(Input02!C12<>"",Input02!C12,"") -> L | D20: =process02!BF23 | E20: =process02!BG23 | F20: =process02!BH23 | G20: =process02!BI23 | H20: =process02!BJ23 | I20: =process02!BK23 | J20: =process02!BL23 | K20: =process02!BM23 | ... BA20: =process02!DC23 | BB20: =IF(Input02!CG12<>"",Input02!CG12,"")
A21: =IF(Input02!A13<>"",Input02!A13,"") -> 8 | B21: =IF(Input02!B13<>"",Input02!B13,"") -> AMELLIA AZZAH | C21: =IF(Input02!C13<>"",Input02!C13,"") -> P | D21: =process02!BF24 | E21: =process02!BG24 | F21: =process02!BH24 | G21: =process02!BI24 | H21: =process02!BJ24 | I21: =process02!BK24 | J21: =process02!BL24 | K21: =process02!BM24 | ... BA21: =process02!DC24 | BB21: =IF(Input02!CG13<>"",Input02!CG13,"")
A22: =IF(Input02!A14<>"",Input02!A14,"") -> 9 | B22: =IF(Input02!B14<>"",Input02!B14,"") -> ESTI ZAINAB SA'ADAH | C22: =IF(Input02!C14<>"",Input02!C14,"") -> P | D22: =process02!BF25 | E22: =process02!BG25 | F22: =process02!BH25 | G22: =process02!BI25 | H22: =process02!BJ25 | I22: =process02!BK25 | J22: =process02!BL25 | K22: =process02!BM25 | ... BA22: =process02!DC25 | BB22: =IF(Input02!CG14<>"",Input02!CG14,"")
A23: =IF(Input02!A15<>"",Input02!A15,"") -> 10 | B23: =IF(Input02!B15<>"",Input02!B15,"") -> FILZA MAWADATUN NISA | C23: =IF(Input02!C15<>"",Input02!C15,"") -> P | D23: =process02!BF26 | E23: =process02!BG26 | F23: =process02!BH26 | G23: =process02!BI26 | H23: =process02!BJ26 | I23: =process02!BK26 | J23: =process02!BL26 | K23: =process02!BM26 | ... BA23: =process02!DC26 | BB23: =IF(Input02!CG15<>"",Input02!CG15,"")
A24: =IF(Input02!A16<>"",Input02!A16,"") -> 11 | B24: =IF(Input02!B16<>"",Input02!B16,"") -> HERLINA TASKIA NUFUS | C24: =IF(Input02!C16<>"",Input02!C16,"") -> P | D24: =process02!BF27 | E24: =process02!BG27 | F24: =process02!BH27 | G24: =process02!BI27 | H24: =process02!BJ27 | I24: =process02!BK27 | J24: =process02!BL27 | K24: =process02!BM27 | ... BA24: =process02!DC27 | BB24: =IF(Input02!CG16<>"",Input02!CG16,"")
A25: =IF(Input02!A17<>"",Input02!A17,"") -> 12 | B25: =IF(Input02!B17<>"",Input02!B17,"") -> IRFANGI MAULANA AJRI | C25: =IF(Input02!C17<>"",Input02!C17,"") -> L | D25: =process02!BF28 | E25: =process02!BG28 | F25: =process02!BH28 | G25: =process02!BI28 | H25: =process02!BJ28 | I25: =process02!BK28 | J25: =process02!BL28 | K25: =process02!BM28 | ... BA25: =process02!DC28 | BB25: =IF(Input02!CG17<>"",Input02!CG17,"")
... A213: =IF(Input02!A205<>"",Input02!A205,"") -> 200 | B213: =IF(Input02!B205<>"",Input02!B205,"") | C213: =IF(Input02!C205<>"",Input02!C205,"") | D213: =process02!BF216 | E213: =process02!BG216 | F213: =process02!BH216 | G213: =process02!BI216 | H213: =process02!BJ216 | I213: =process02!BK216 | J213: =process02!BL216 | K213: =process02!BM216 | ... BA213: =process02!DC216 | BB213: =IF(Input02!CG205<>"",Input02!CG205,"")
A215: Keterangan:
B216: Jawaban salah

Sheet Data03
A2: Skor Jawaban Soal Isian Singkat
B4: Satuan Pendidikan | C4: =": "&Input01!B7 -> : MA Salafiyah Bantarsari
B5: Nama Tes | C5: =": "&Input01!B10 -> : Asesmen Sumatif Tengah Semester (ASTS)
B6: Mata Pelajaran | C6: =": "&Input01!B8 -> : Informatika
B7: Kelas/Program | C7: =": "&Input01!B9 -> : Fase F XI 5
B8: Tanggal Tes | C8: =": "&Input01!B16 -> : 23 September 2026
B9: Nama Guru | C9: =": "&Input01!B12 -> : Abdul Mu'iz
A11: No | B11: Nama | C11: Jenis Kelamin | D11: Nomor Soal
D12: 1 | E12: 2 | F12: 3 | G12: 4 | H12: 5 | I12: 6 | J12: 7 | K12: 8 | L12: 9 | M12: 10 | N12: 11 | O12: 12 | P12: 13 | Q12: 14 | R12: 15 | S12: 16 | T12: 17 | U12: 18 | V12: 19 | W12: 20
A13: -1 | B13: -2 | C13: -3 | D13: -4 | E13: -5 | F13: -6 | G13: -7 | H13: -8 | I13: -9 | J13: -10 | K13: -11 | L13: -12 | M13: -13 | N13: -14 | O13: -15 | P13: -16 | Q13: -17 | R13: -18 | S13: -19 | T13: -20 | U13: -21 | V13: -22 | W13: -23
A14: =IF(Input02!A6<>"",Input02!A6,"") -> 1 | B14: =IF(Input02!B6<>"",Input02!B6,"") -> ACHMAD FADILATUL KHANAN | C14: =IF(Input02!C6<>"",Input02!C6,"") -> L | D14: =IF(Input02!BB6<>"",Input02!BB6,"") -> 2 | E14: =IF(Input02!BC6<>"",Input02!BC6,"") -> 2 | F14: =IF(Input02!BD6<>"",Input02!BD6,"") -> 2 | G14: =IF(Input02!BE6<>"",Input02!BE6,"") -> 2 | H14: =IF(Input02!BF6<>"",Input02!BF6,"") -> 2 | I14: =IF(Input02!BG6<>"",Input02!BG6,"") | J14: =IF(Input02!BH6<>"",Input02!BH6,"") | K14: =IF(Input02!BI6<>"",Input02!BI6,"") | ... W14: =IF(Input02!BU6<>"",Input02!BU6,"")
A15: =IF(Input02!A7<>"",Input02!A7,"") -> 2 | B15: =IF(Input02!B7<>"",Input02!B7,"") -> AFRISA KHOERUNNISA | C15: =IF(Input02!C7<>"",Input02!C7,"") -> P | D15: =IF(Input02!BB7<>"",Input02!BB7,"") -> 2 | E15: =IF(Input02!BC7<>"",Input02!BC7,"") -> 2 | F15: =IF(Input02!BD7<>"",Input02!BD7,"") -> 2 | G15: =IF(Input02!BE7<>"",Input02!BE7,"") -> 2 | H15: =IF(Input02!BF7<>"",Input02!BF7,"") -> 2 | I15: =IF(Input02!BG7<>"",Input02!BG7,"") | J15: =IF(Input02!BH7<>"",Input02!BH7,"") | K15: =IF(Input02!BI7<>"",Input02!BI7,"") | ... W15: =IF(Input02!BU7<>"",Input02!BU7,"")
A16: =IF(Input02!A8<>"",Input02!A8,"") -> 3 | B16: =IF(Input02!B8<>"",Input02!B8,"") -> AHMAD SYAHRIAN RAMADAN | C16: =IF(Input02!C8<>"",Input02!C8,"") -> L | D16: =IF(Input02!BB8<>"",Input02!BB8,"") | E16: =IF(Input02!BC8<>"",Input02!BC8,"") | F16: =IF(Input02!BD8<>"",Input02!BD8,"") | G16: =IF(Input02!BE8<>"",Input02!BE8,"") | H16: =IF(Input02!BF8<>"",Input02!BF8,"") | I16: =IF(Input02!BG8<>"",Input02!BG8,"") | J16: =IF(Input02!BH8<>"",Input02!BH8,"") | K16: =IF(Input02!BI8<>"",Input02!BI8,"") | ... W16: =IF(Input02!BU8<>"",Input02!BU8,"")
A17: =IF(Input02!A9<>"",Input02!A9,"") -> 4 | B17: =IF(Input02!B9<>"",Input02!B9,"") -> AHMAD ULUN NUHA | C17: =IF(Input02!C9<>"",Input02!C9,"") -> L | D17: =IF(Input02!BB9<>"",Input02!BB9,"") | E17: =IF(Input02!BC9<>"",Input02!BC9,"") | F17: =IF(Input02!BD9<>"",Input02!BD9,"") | G17: =IF(Input02!BE9<>"",Input02!BE9,"") | H17: =IF(Input02!BF9<>"",Input02!BF9,"") | I17: =IF(Input02!BG9<>"",Input02!BG9,"") | J17: =IF(Input02!BH9<>"",Input02!BH9,"") | K17: =IF(Input02!BI9<>"",Input02!BI9,"") | ... W17: =IF(Input02!BU9<>"",Input02!BU9,"")
A18: =IF(Input02!A10<>"",Input02!A10,"") -> 5 | B18: =IF(Input02!B10<>"",Input02!B10,"") -> AHSINUL MUTHORIQ | C18: =IF(Input02!C10<>"",Input02!C10,"") -> L | D18: =IF(Input02!BB10<>"",Input02!BB10,"") | E18: =IF(Input02!BC10<>"",Input02!BC10,"") | F18: =IF(Input02!BD10<>"",Input02!BD10,"") | G18: =IF(Input02!BE10<>"",Input02!BE10,"") | H18: =IF(Input02!BF10<>"",Input02!BF10,"") | I18: =IF(Input02!BG10<>"",Input02!BG10,"") | J18: =IF(Input02!BH10<>"",Input02!BH10,"") | K18: =IF(Input02!BI10<>"",Input02!BI10,"") | ... W18: =IF(Input02!BU10<>"",Input02!BU10,"")
A19: =IF(Input02!A11<>"",Input02!A11,"") -> 6 | B19: =IF(Input02!B11<>"",Input02!B11,"") -> ALFIN ARDIANSYAH NAWAWI | C19: =IF(Input02!C11<>"",Input02!C11,"") -> L | D19: =IF(Input02!BB11<>"",Input02!BB11,"") | E19: =IF(Input02!BC11<>"",Input02!BC11,"") | F19: =IF(Input02!BD11<>"",Input02!BD11,"") | G19: =IF(Input02!BE11<>"",Input02!BE11,"") | H19: =IF(Input02!BF11<>"",Input02!BF11,"") | I19: =IF(Input02!BG11<>"",Input02!BG11,"") | J19: =IF(Input02!BH11<>"",Input02!BH11,"") | K19: =IF(Input02!BI11<>"",Input02!BI11,"") | ... W19: =IF(Input02!BU11<>"",Input02!BU11,"")
A20: =IF(Input02!A12<>"",Input02!A12,"") -> 7 | B20: =IF(Input02!B12<>"",Input02!B12,"") -> ALIF KHISBULLOH | C20: =IF(Input02!C12<>"",Input02!C12,"") -> L | D20: =IF(Input02!BB12<>"",Input02!BB12,"") | E20: =IF(Input02!BC12<>"",Input02!BC12,"") | F20: =IF(Input02!BD12<>"",Input02!BD12,"") | G20: =IF(Input02!BE12<>"",Input02!BE12,"") | H20: =IF(Input02!BF12<>"",Input02!BF12,"") | I20: =IF(Input02!BG12<>"",Input02!BG12,"") | J20: =IF(Input02!BH12<>"",Input02!BH12,"") | K20: =IF(Input02!BI12<>"",Input02!BI12,"") | ... W20: =IF(Input02!BU12<>"",Input02!BU12,"")
A21: =IF(Input02!A13<>"",Input02!A13,"") -> 8 | B21: =IF(Input02!B13<>"",Input02!B13,"") -> AMELLIA AZZAH | C21: =IF(Input02!C13<>"",Input02!C13,"") -> P | D21: =IF(Input02!BB13<>"",Input02!BB13,"") | E21: =IF(Input02!BC13<>"",Input02!BC13,"") | F21: =IF(Input02!BD13<>"",Input02!BD13,"") | G21: =IF(Input02!BE13<>"",Input02!BE13,"") | H21: =IF(Input02!BF13<>"",Input02!BF13,"") | I21: =IF(Input02!BG13<>"",Input02!BG13,"") | J21: =IF(Input02!BH13<>"",Input02!BH13,"") | K21: =IF(Input02!BI13<>"",Input02!BI13,"") | ... W21: =IF(Input02!BU13<>"",Input02!BU13,"")
A22: =IF(Input02!A14<>"",Input02!A14,"") -> 9 | B22: =IF(Input02!B14<>"",Input02!B14,"") -> ESTI ZAINAB SA'ADAH | C22: =IF(Input02!C14<>"",Input02!C14,"") -> P | D22: =IF(Input02!BB14<>"",Input02!BB14,"") | E22: =IF(Input02!BC14<>"",Input02!BC14,"") | F22: =IF(Input02!BD14<>"",Input02!BD14,"") | G22: =IF(Input02!BE14<>"",Input02!BE14,"") | H22: =IF(Input02!BF14<>"",Input02!BF14,"") | I22: =IF(Input02!BG14<>"",Input02!BG14,"") | J22: =IF(Input02!BH14<>"",Input02!BH14,"") | K22: =IF(Input02!BI14<>"",Input02!BI14,"") | ... W22: =IF(Input02!BU14<>"",Input02!BU14,"")
A23: =IF(Input02!A15<>"",Input02!A15,"") -> 10 | B23: =IF(Input02!B15<>"",Input02!B15,"") -> FILZA MAWADATUN NISA | C23: =IF(Input02!C15<>"",Input02!C15,"") -> P | D23: =IF(Input02!BB15<>"",Input02!BB15,"") | E23: =IF(Input02!BC15<>"",Input02!BC15,"") | F23: =IF(Input02!BD15<>"",Input02!BD15,"") | G23: =IF(Input02!BE15<>"",Input02!BE15,"") | H23: =IF(Input02!BF15<>"",Input02!BF15,"") | I23: =IF(Input02!BG15<>"",Input02!BG15,"") | J23: =IF(Input02!BH15<>"",Input02!BH15,"") | K23: =IF(Input02!BI15<>"",Input02!BI15,"") | ... W23: =IF(Input02!BU15<>"",Input02!BU15,"")
A24: =IF(Input02!A16<>"",Input02!A16,"") -> 11 | B24: =IF(Input02!B16<>"",Input02!B16,"") -> HERLINA TASKIA NUFUS | C24: =IF(Input02!C16<>"",Input02!C16,"") -> P | D24: =IF(Input02!BB16<>"",Input02!BB16,"") | E24: =IF(Input02!BC16<>"",Input02!BC16,"") | F24: =IF(Input02!BD16<>"",Input02!BD16,"") | G24: =IF(Input02!BE16<>"",Input02!BE16,"") | H24: =IF(Input02!BF16<>"",Input02!BF16,"") | I24: =IF(Input02!BG16<>"",Input02!BG16,"") | J24: =IF(Input02!BH16<>"",Input02!BH16,"") | K24: =IF(Input02!BI16<>"",Input02!BI16,"") | ... W24: =IF(Input02!BU16<>"",Input02!BU16,"")
A25: =IF(Input02!A17<>"",Input02!A17,"") -> 12 | B25: =IF(Input02!B17<>"",Input02!B17,"") -> IRFANGI MAULANA AJRI | C25: =IF(Input02!C17<>"",Input02!C17,"") -> L | D25: =IF(Input02!BB17<>"",Input02!BB17,"") | E25: =IF(Input02!BC17<>"",Input02!BC17,"") | F25: =IF(Input02!BD17<>"",Input02!BD17,"") | G25: =IF(Input02!BE17<>"",Input02!BE17,"") | H25: =IF(Input02!BF17<>"",Input02!BF17,"") | I25: =IF(Input02!BG17<>"",Input02!BG17,"") | J25: =IF(Input02!BH17<>"",Input02!BH17,"") | K25: =IF(Input02!BI17<>"",Input02!BI17,"") | ... W25: =IF(Input02!BU17<>"",Input02!BU17,"")
... A213: =IF(Input02!A205<>"",Input02!A205,"") -> 200 | B213: =IF(Input02!B205<>"",Input02!B205,"") | C213: =IF(Input02!C205<>"",Input02!C205,"") | D213: =IF(Input02!BB205<>"",Input02!BB205,"") | E213: =IF(Input02!BC205<>"",Input02!BC205,"") | F213: =IF(Input02!BD205<>"",Input02!BD205,"") | G213: =IF(Input02!BE205<>"",Input02!BE205,"") | H213: =IF(Input02!BF205<>"",Input02!BF205,"") | I213: =IF(Input02!BG205<>"",Input02!BG205,"") | J213: =IF(Input02!BH205<>"",Input02!BH205,"") | K213: =IF(Input02!BI205<>"",Input02!BI205,"") | ... W213: =IF(Input02!BU205<>"",Input02!BU205,"")

Sheet Data02
A2: Skor Jawaban Soal Essay
B4: Satuan Pendidikan | C4: =": "&Input01!B7 -> : MA Salafiyah Bantarsari
B5: Nama Tes | C5: =": "&Input01!B10 -> : Asesmen Sumatif Tengah Semester (ASTS)
B6: Mata Pelajaran | C6: =": "&Input01!B8 -> : Informatika
B7: Kelas/Program | C7: =": "&Input01!B9 -> : Fase F XI 5
B8: Tanggal Tes | C8: =": "&Input01!B16 -> : 23 September 2026
B9: Nama Guru | C9: =": "&Input01!B12 -> : Abdul Mu'iz
A11: No | B11: Nama | C11: Jenis Kelamin | D11: Nomor Soal
D12: 1 | E12: 2 | F12: 3 | G12: 4 | H12: 5 | I12: 6 | J12: 7 | K12: 8 | L12: 9 | M12: 10
A13: -1 | B13: -2 | C13: -3 | D13: -4 | E13: -5 | F13: -6 | G13: -7 | H13: -8 | I13: -9 | J13: -10 | K13: -11 | L13: -12 | M13: -13
A14: =IF(Input02!A6<>"",Input02!A6,"") -> 1 | B14: =IF(Input02!B6<>"",Input02!B6,"") -> ACHMAD FADILATUL KHANAN | C14: =IF(Input02!C6<>"",Input02!C6,"") -> L | D14: =IF(Input02!BV6<>"",Input02!BV6,"") | E14: =IF(Input02!BW6<>"",Input02!BW6,"") | F14: =IF(Input02!BX6<>"",Input02!BX6,"") | G14: =IF(Input02!BY6<>"",Input02!BY6,"") | H14: =IF(Input02!BZ6<>"",Input02!BZ6,"") | I14: =IF(Input02!CA6<>"",Input02!CA6,"") | J14: =IF(Input02!CB6<>"",Input02!CB6,"") | K14: =IF(Input02!CC6<>"",Input02!CC6,"") | ... M14: =IF(Input02!CE6<>"",Input02!CE6,"")
A15: =IF(Input02!A7<>"",Input02!A7,"") -> 2 | B15: =IF(Input02!B7<>"",Input02!B7,"") -> AFRISA KHOERUNNISA | C15: =IF(Input02!C7<>"",Input02!C7,"") -> P | D15: =IF(Input02!BV7<>"",Input02!BV7,"") | E15: =IF(Input02!BW7<>"",Input02!BW7,"") | F15: =IF(Input02!BX7<>"",Input02!BX7,"") | G15: =IF(Input02!BY7<>"",Input02!BY7,"") | H15: =IF(Input02!BZ7<>"",Input02!BZ7,"") | I15: =IF(Input02!CA7<>"",Input02!CA7,"") | J15: =IF(Input02!CB7<>"",Input02!CB7,"") | K15: =IF(Input02!CC7<>"",Input02!CC7,"") | ... M15: =IF(Input02!CE7<>"",Input02!CE7,"")
A16: =IF(Input02!A8<>"",Input02!A8,"") -> 3 | B16: =IF(Input02!B8<>"",Input02!B8,"") -> AHMAD SYAHRIAN RAMADAN | C16: =IF(Input02!C8<>"",Input02!C8,"") -> L | D16: =IF(Input02!BV8<>"",Input02!BV8,"") | E16: =IF(Input02!BW8<>"",Input02!BW8,"") | F16: =IF(Input02!BX8<>"",Input02!BX8,"") | G16: =IF(Input02!BY8<>"",Input02!BY8,"") | H16: =IF(Input02!BZ8<>"",Input02!BZ8,"") | I16: =IF(Input02!CA8<>"",Input02!CA8,"") | J16: =IF(Input02!CB8<>"",Input02!CB8,"") | K16: =IF(Input02!CC8<>"",Input02!CC8,"") | ... M16: =IF(Input02!CE8<>"",Input02!CE8,"")
A17: =IF(Input02!A9<>"",Input02!A9,"") -> 4 | B17: =IF(Input02!B9<>"",Input02!B9,"") -> AHMAD ULUN NUHA | C17: =IF(Input02!C9<>"",Input02!C9,"") -> L | D17: =IF(Input02!BV9<>"",Input02!BV9,"") | E17: =IF(Input02!BW9<>"",Input02!BW9,"") | F17: =IF(Input02!BX9<>"",Input02!BX9,"") | G17: =IF(Input02!BY9<>"",Input02!BY9,"") | H17: =IF(Input02!BZ9<>"",Input02!BZ9,"") | I17: =IF(Input02!CA9<>"",Input02!CA9,"") | J17: =IF(Input02!CB9<>"",Input02!CB9,"") | K17: =IF(Input02!CC9<>"",Input02!CC9,"") | ... M17: =IF(Input02!CE9<>"",Input02!CE9,"")
A18: =IF(Input02!A10<>"",Input02!A10,"") -> 5 | B18: =IF(Input02!B10<>"",Input02!B10,"") -> AHSINUL MUTHORIQ | C18: =IF(Input02!C10<>"",Input02!C10,"") -> L | D18: =IF(Input02!BV10<>"",Input02!BV10,"") | E18: =IF(Input02!BW10<>"",Input02!BW10,"") | F18: =IF(Input02!BX10<>"",Input02!BX10,"") | G18: =IF(Input02!BY10<>"",Input02!BY10,"") | H18: =IF(Input02!BZ10<>"",Input02!BZ10,"") | I18: =IF(Input02!CA10<>"",Input02!CA10,"") | J18: =IF(Input02!CB10<>"",Input02!CB10,"") | K18: =IF(Input02!CC10<>"",Input02!CC10,"") | ... M18: =IF(Input02!CE10<>"",Input02!CE10,"")
A19: =IF(Input02!A11<>"",Input02!A11,"") -> 6 | B19: =IF(Input02!B11<>"",Input02!B11,"") -> ALFIN ARDIANSYAH NAWAWI | C19: =IF(Input02!C11<>"",Input02!C11,"") -> L | D19: =IF(Input02!BV11<>"",Input02!BV11,"") | E19: =IF(Input02!BW11<>"",Input02!BW11,"") | F19: =IF(Input02!BX11<>"",Input02!BX11,"") | G19: =IF(Input02!BY11<>"",Input02!BY11,"") | H19: =IF(Input02!BZ11<>"",Input02!BZ11,"") | I19: =IF(Input02!CA11<>"",Input02!CA11,"") | J19: =IF(Input02!CB11<>"",Input02!CB11,"") | K19: =IF(Input02!CC11<>"",Input02!CC11,"") | ... M19: =IF(Input02!CE11<>"",Input02!CE11,"")
A20: =IF(Input02!A12<>"",Input02!A12,"") -> 7 | B20: =IF(Input02!B12<>"",Input02!B12,"") -> ALIF KHISBULLOH | C20: =IF(Input02!C12<>"",Input02!C12,"") -> L | D20: =IF(Input02!BV12<>"",Input02!BV12,"") | E20: =IF(Input02!BW12<>"",Input02!BW12,"") | F20: =IF(Input02!BX12<>"",Input02!BX12,"") | G20: =IF(Input02!BY12<>"",Input02!BY12,"") | H20: =IF(Input02!BZ12<>"",Input02!BZ12,"") | I20: =IF(Input02!CA12<>"",Input02!CA12,"") | J20: =IF(Input02!CB12<>"",Input02!CB12,"") | K20: =IF(Input02!CC12<>"",Input02!CC12,"") | ... M20: =IF(Input02!CE12<>"",Input02!CE12,"")
A21: =IF(Input02!A13<>"",Input02!A13,"") -> 8 | B21: =IF(Input02!B13<>"",Input02!B13,"") -> AMELLIA AZZAH | C21: =IF(Input02!C13<>"",Input02!C13,"") -> P | D21: =IF(Input02!BV13<>"",Input02!BV13,"") | E21: =IF(Input02!BW13<>"",Input02!BW13,"") | F21: =IF(Input02!BX13<>"",Input02!BX13,"") | G21: =IF(Input02!BY13<>"",Input02!BY13,"") | H21: =IF(Input02!BZ13<>"",Input02!BZ13,"") | I21: =IF(Input02!CA13<>"",Input02!CA13,"") | J21: =IF(Input02!CB13<>"",Input02!CB13,"") | K21: =IF(Input02!CC13<>"",Input02!CC13,"") | ... M21: =IF(Input02!CE13<>"",Input02!CE13,"")
A22: =IF(Input02!A14<>"",Input02!A14,"") -> 9 | B22: =IF(Input02!B14<>"",Input02!B14,"") -> ESTI ZAINAB SA'ADAH | C22: =IF(Input02!C14<>"",Input02!C14,"") -> P | D22: =IF(Input02!BV14<>"",Input02!BV14,"") | E22: =IF(Input02!BW14<>"",Input02!BW14,"") | F22: =IF(Input02!BX14<>"",Input02!BX14,"") | G22: =IF(Input02!BY14<>"",Input02!BY14,"") | H22: =IF(Input02!BZ14<>"",Input02!BZ14,"") | I22: =IF(Input02!CA14<>"",Input02!CA14,"") | J22: =IF(Input02!CB14<>"",Input02!CB14,"") | K22: =IF(Input02!CC14<>"",Input02!CC14,"") | ... M22: =IF(Input02!CE14<>"",Input02!CE14,"")
A23: =IF(Input02!A15<>"",Input02!A15,"") -> 10 | B23: =IF(Input02!B15<>"",Input02!B15,"") -> FILZA MAWADATUN NISA | C23: =IF(Input02!C15<>"",Input02!C15,"") -> P | D23: =IF(Input02!BV15<>"",Input02!BV15,"") | E23: =IF(Input02!BW15<>"",Input02!BW15,"") | F23: =IF(Input02!BX15<>"",Input02!BX15,"") | G23: =IF(Input02!BY15<>"",Input02!BY15,"") | H23: =IF(Input02!BZ15<>"",Input02!BZ15,"") | I23: =IF(Input02!CA15<>"",Input02!CA15,"") | J23: =IF(Input02!CB15<>"",Input02!CB15,"") | K23: =IF(Input02!CC15<>"",Input02!CC15,"") | ... M23: =IF(Input02!CE15<>"",Input02!CE15,"")
A24: =IF(Input02!A16<>"",Input02!A16,"") -> 11 | B24: =IF(Input02!B16<>"",Input02!B16,"") -> HERLINA TASKIA NUFUS | C24: =IF(Input02!C16<>"",Input02!C16,"") -> P | D24: =IF(Input02!BV16<>"",Input02!BV16,"") | E24: =IF(Input02!BW16<>"",Input02!BW16,"") | F24: =IF(Input02!BX16<>"",Input02!BX16,"") | G24: =IF(Input02!BY16<>"",Input02!BY16,"") | H24: =IF(Input02!BZ16<>"",Input02!BZ16,"") | I24: =IF(Input02!CA16<>"",Input02!CA16,"") | J24: =IF(Input02!CB16<>"",Input02!CB16,"") | K24: =IF(Input02!CC16<>"",Input02!CC16,"") | ... M24: =IF(Input02!CE16<>"",Input02!CE16,"")
A25: =IF(Input02!A17<>"",Input02!A17,"") -> 12 | B25: =IF(Input02!B17<>"",Input02!B17,"") -> IRFANGI MAULANA AJRI | C25: =IF(Input02!C17<>"",Input02!C17,"") -> L | D25: =IF(Input02!BV17<>"",Input02!BV17,"") | E25: =IF(Input02!BW17<>"",Input02!BW17,"") | F25: =IF(Input02!BX17<>"",Input02!BX17,"") | G25: =IF(Input02!BY17<>"",Input02!BY17,"") | H25: =IF(Input02!BZ17<>"",Input02!BZ17,"") | I25: =IF(Input02!CA17<>"",Input02!CA17,"") | J25: =IF(Input02!CB17<>"",Input02!CB17,"") | K25: =IF(Input02!CC17<>"",Input02!CC17,"") | ... M25: =IF(Input02!CE17<>"",Input02!CE17,"")
... A213: =IF(Input02!A205<>"",Input02!A205,"") -> 200 | B213: =IF(Input02!B205<>"",Input02!B205,"") | C213: =IF(Input02!C205<>"",Input02!C205,"") | D213: =IF(Input02!BV205<>"",Input02!BV205,"") | E213: =IF(Input02!BW205<>"",Input02!BW205,"") | F213: =IF(Input02!BX205<>"",Input02!BX205,"") | G213: =IF(Input02!BY205<>"",Input02!BY205,"") | H213: =IF(Input02!BZ205<>"",Input02!BZ205,"") | I213: =IF(Input02!CA205<>"",Input02!CA205,"") | J213: =IF(Input02!CB205<>"",Input02!CB205,"") | K213: =IF(Input02!CC205<>"",Input02!CC205,"") | ... M213: =IF(Input02!CE205<>"",Input02!CE205,"")

Sheet Peserta
A2: DAFTAR NILAI SISWA
A4: =Input01!A7 -> Satuan Pendidikan | D4: =": "&Input01!B7 -> : MA Salafiyah Bantarsari
A5: =Input01!A10 -> Nama Tes | D5: =": "&Input01!B10 -> : Asesmen Sumatif Tengah Semester (ASTS)
A6: =Input01!A8 -> Mata Pelajaran | D6: =": "&Input01!B8 -> : Informatika
A7: =Input01!A9 -> Kelas/Program | D7: =": "&Input01!B9 -> : Fase F XI 5 | K7: KKM
A8: =Input01!A16 -> Tanggal Tes | D8: =": "&Input01!B16 -> : 23 September 2026 | K8: =Input01!B23 -> 67
A9: =Input01!A11 -> Pokok Bahasan/Sub | D9: =": "&Input01!B11 -> : Bab 1, 2
A10: No | B10: Nama Peserta | C10: L/P | D10: ="Tes Objektif ("&Input01!B29*100&"%)" -> Tes Objektif (100%) | G10: ="Nilai Tes Isian ("&Input01!B30*100&"%)" -> Nilai Tes Isian (100%) | H10: ="Nilai Tes Essay ("&Input01!B31*100&"%)" -> Nilai Tes Essay (0%) | I10: Nilai Akhir | J10: Predikat | K10: Keterangan
D11: Benar | E11: Salah | F11: Nilai
A12: -1 | B12: -2 | C12: -3 | D12: -4 | E12: -5 | F12: -6 | G12: -7 | H12: -8 | I12: -9 | J12: -10 | K12: -11
A13: 1 | B13: =IF(Input02!B6="","",Input02!B6) -> ACHMAD FADILATUL KHANAN | C13: =IF(Input02!C6="","",Input02!C6) -> L | D13: =IF(process02!DD17="","",process02!DD17) -> 3 | E13: =IF(process02!DE17="","",process02!DE17) -> 32 | F13: =IF(process01!C8="","",process01!C8) -> 8.5714286 | G13: =IF(process01!T8="","",process01!T8) -> 200 | H13: =IF(process01!U8="","",process01!U8) -> 0 | I13: =IF(process01!X8="","",process01!X8) -> 208.57143 | J13: =IF(process01!Y8="","",process01!Y8) -> A | K13: =IF(I13="","",IF(process01!Z8=0,"Belum tuntas","Tuntas")) -> Tuntas
A14: =A13+1 -> 2 | B14: =IF(Input02!B7="","",Input02!B7) -> AFRISA KHOERUNNISA | C14: =IF(Input02!C7="","",Input02!C7) -> P | D14: =IF(process02!DD18="","",process02!DD18) -> 7 | E14: =IF(process02!DE18="","",process02!DE18) -> 28 | F14: =IF(process01!C9="","",process01!C9) -> 20 | G14: =IF(process01!T9="","",process01!T9) -> 200 | H14: =IF(process01!U9="","",process01!U9) -> 0 | I14: =IF(process01!X9="","",process01!X9) -> 220 | J14: =IF(process01!Y9="","",process01!Y9) -> A | K14: =IF(I14="","",IF(process01!Z9=0,"Belum tuntas","Tuntas")) -> Tuntas
A15: =A14+1 -> 3 | B15: =IF(Input02!B8="","",Input02!B8) -> AHMAD SYAHRIAN RAMADAN | C15: =IF(Input02!C8="","",Input02!C8) -> L | D15: =IF(process02!DD19="","",process02!DD19) | E15: =IF(process02!DE19="","",process02!DE19) | F15: =IF(process01!C10="","",process01!C10) | G15: =IF(process01!T10="","",process01!T10) -> 0 | H15: =IF(process01!U10="","",process01!U10) -> 0 | I15: =IF(process01!X10="","",process01!X10) | J15: =IF(process01!Y10="","",process01!Y10) | K15: =IF(I15="","",IF(process01!Z10=0,"Belum tuntas","Tuntas"))
A16: =A15+1 -> 4 | B16: =IF(Input02!B9="","",Input02!B9) -> AHMAD ULUN NUHA | C16: =IF(Input02!C9="","",Input02!C9) -> L | D16: =IF(process02!DD20="","",process02!DD20) | E16: =IF(process02!DE20="","",process02!DE20) | F16: =IF(process01!C11="","",process01!C11) | G16: =IF(process01!T11="","",process01!T11) -> 0 | H16: =IF(process01!U11="","",process01!U11) -> 0 | I16: =IF(process01!X11="","",process01!X11) | J16: =IF(process01!Y11="","",process01!Y11) | K16: =IF(I16="","",IF(process01!Z11=0,"Belum tuntas","Tuntas"))
A17: =A16+1 -> 5 | B17: =IF(Input02!B10="","",Input02!B10) -> AHSINUL MUTHORIQ | C17: =IF(Input02!C10="","",Input02!C10) -> L | D17: =IF(process02!DD21="","",process02!DD21) | E17: =IF(process02!DE21="","",process02!DE21) | F17: =IF(process01!C12="","",process01!C12) | G17: =IF(process01!T12="","",process01!T12) -> 0 | H17: =IF(process01!U12="","",process01!U12) -> 0 | I17: =IF(process01!X12="","",process01!X12) | J17: =IF(process01!Y12="","",process01!Y12) | K17: =IF(I17="","",IF(process01!Z12=0,"Belum tuntas","Tuntas"))
A18: =A17+1 -> 6 | B18: =IF(Input02!B11="","",Input02!B11) -> ALFIN ARDIANSYAH NAWAWI | C18: =IF(Input02!C11="","",Input02!C11) -> L | D18: =IF(process02!DD22="","",process02!DD22) | E18: =IF(process02!DE22="","",process02!DE22) | F18: =IF(process01!C13="","",process01!C13) | G18: =IF(process01!T13="","",process01!T13) -> 0 | H18: =IF(process01!U13="","",process01!U13) -> 0 | I18: =IF(process01!X13="","",process01!X13) | J18: =IF(process01!Y13="","",process01!Y13) | K18: =IF(I18="","",IF(process01!Z13=0,"Belum tuntas","Tuntas"))
A19: =A18+1 -> 7 | B19: =IF(Input02!B12="","",Input02!B12) -> ALIF KHISBULLOH | C19: =IF(Input02!C12="","",Input02!C12) -> L | D19: =IF(process02!DD23="","",process02!DD23) | E19: =IF(process02!DE23="","",process02!DE23) | F19: =IF(process01!C14="","",process01!C14) | G19: =IF(process01!T14="","",process01!T14) -> 0 | H19: =IF(process01!U14="","",process01!U14) -> 0 | I19: =IF(process01!X14="","",process01!X14) | J19: =IF(process01!Y14="","",process01!Y14) | K19: =IF(I19="","",IF(process01!Z14=0,"Belum tuntas","Tuntas"))
A20: =A19+1 -> 8 | B20: =IF(Input02!B13="","",Input02!B13) -> AMELLIA AZZAH | C20: =IF(Input02!C13="","",Input02!C13) -> P | D20: =IF(process02!DD24="","",process02!DD24) | E20: =IF(process02!DE24="","",process02!DE24) | F20: =IF(process01!C15="","",process01!C15) | G20: =IF(process01!T15="","",process01!T15) -> 0 | H20: =IF(process01!U15="","",process01!U15) -> 0 | I20: =IF(process01!X15="","",process01!X15) | J20: =IF(process01!Y15="","",process01!Y15) | K20: =IF(I20="","",IF(process01!Z15=0,"Belum tuntas","Tuntas"))
A21: =A20+1 -> 9 | B21: =IF(Input02!B14="","",Input02!B14) -> ESTI ZAINAB SA'ADAH | C21: =IF(Input02!C14="","",Input02!C14) -> P | D21: =IF(process02!DD25="","",process02!DD25) | E21: =IF(process02!DE25="","",process02!DE25) | F21: =IF(process01!C16="","",process01!C16) | G21: =IF(process01!T16="","",process01!T16) -> 0 | H21: =IF(process01!U16="","",process01!U16) -> 0 | I21: =IF(process01!X16="","",process01!X16) | J21: =IF(process01!Y16="","",process01!Y16) | K21: =IF(I21="","",IF(process01!Z16=0,"Belum tuntas","Tuntas"))
A22: =A21+1 -> 10 | B22: =IF(Input02!B15="","",Input02!B15) -> FILZA MAWADATUN NISA | C22: =IF(Input02!C15="","",Input02!C15) -> P | D22: =IF(process02!DD26="","",process02!DD26) | E22: =IF(process02!DE26="","",process02!DE26) | F22: =IF(process01!C17="","",process01!C17) | G22: =IF(process01!T17="","",process01!T17) -> 0 | H22: =IF(process01!U17="","",process01!U17) -> 0 | I22: =IF(process01!X17="","",process01!X17) | J22: =IF(process01!Y17="","",process01!Y17) | K22: =IF(I22="","",IF(process01!Z17=0,"Belum tuntas","Tuntas"))
A23: =A22+1 -> 11 | B23: =IF(Input02!B16="","",Input02!B16) -> HERLINA TASKIA NUFUS | C23: =IF(Input02!C16="","",Input02!C16) -> P | D23: =IF(process02!DD27="","",process02!DD27) | E23: =IF(process02!DE27="","",process02!DE27) | F23: =IF(process01!C18="","",process01!C18) | G23: =IF(process01!T18="","",process01!T18) -> 0 | H23: =IF(process01!U18="","",process01!U18) -> 0 | I23: =IF(process01!X18="","",process01!X18) | J23: =IF(process01!Y18="","",process01!Y18) | K23: =IF(I23="","",IF(process01!Z18=0,"Belum tuntas","Tuntas"))
A24: =A23+1 -> 12 | B24: =IF(Input02!B17="","",Input02!B17) -> IRFANGI MAULANA AJRI | C24: =IF(Input02!C17="","",Input02!C17) -> L | D24: =IF(process02!DD28="","",process02!DD28) | E24: =IF(process02!DE28="","",process02!DE28) | F24: =IF(process01!C19="","",process01!C19) | G24: =IF(process01!T19="","",process01!T19) -> 0 | H24: =IF(process01!U19="","",process01!U19) -> 0 | I24: =IF(process01!X19="","",process01!X19) | J24: =IF(process01!Y19="","",process01!Y19) | K24: =IF(I24="","",IF(process01!Z19=0,"Belum tuntas","Tuntas"))
A25: =A24+1 -> 13 | B25: =IF(Input02!B18="","",Input02!B18) -> IRMA SURYANINGSIH | C25: =IF(Input02!C18="","",Input02!C18) -> P | D25: =IF(process02!DD29="","",process02!DD29) | E25: =IF(process02!DE29="","",process02!DE29) | F25: =IF(process01!C20="","",process01!C20) | G25: =IF(process01!T20="","",process01!T20) -> 0 | H25: =IF(process01!U20="","",process01!U20) -> 0 | I25: =IF(process01!X20="","",process01!X20) | J25: =IF(process01!Y20="","",process01!Y20) | K25: =IF(I25="","",IF(process01!Z20=0,"Belum tuntas","Tuntas"))
... A212: =A211+1 -> 200 | B212: =IF(Input02!B205="","",Input02!B205) | C212: =IF(Input02!C205="","",Input02!C205) | D212: =IF(process02!DD216="","",process02!DD216) | E212: =IF(process02!DE216="","",process02!DE216) | F212: =IF(process01!C207="","",process01!C207) | G212: =IF(process01!T207="","",process01!T207) | H212: =IF(process01!U207="","",process01!U207) | I212: =IF(process01!X207="","",process01!X207) | J212: =IF(process01!Y207="","",process01!Y207) | K212: =IF(I212="","",IF(process01!Z207=0,"Belum tuntas","Tuntas"))
A214: - Jumlah peserta test = | C214: =COUNT(I13:I212) -> 2 | D214: Rata-rata = | F214: =AVERAGE(F13:F213) -> 14.285714 | G214: =AVERAGE(G13:G213) -> 13.333333 | H214: =AVERAGE(H13:H213) -> 0 | I214: =AVERAGE(I13:I213) -> 214.28571
A215: - Jumlah yang tuntas = | C215: =COUNTIF(K13:K212,"Tuntas") -> 2 | D215: Terendah = | F215: =MIN(F13:F213) -> 8.5714286 | G215: =MIN(G13:G213) -> 0 | H215: =MIN(H13:H213) -> 0 | I215: =MIN(I13:I213) -> 208.57143
A216: - Jumlah yang belum tuntas = | C216: =C214-C215 -> 0 | D216: Tertinggi = | F216: =MAX(F13:F213) -> 20 | G216: =MAX(G13:G213) -> 200 | H216: =MAX(H13:H213) -> 0 | I216: =MAX(I13:I213) -> 220
A217: - Persentase peserta tuntas = | C217: =100*C215/C214 -> 100 | D217: Daya Serap = | F217: =F214/Input01!$B$22 -> 0.14285714 | G217: =G214/Input01!$B$22 -> 0.13333333 | H217: =H214/Input01!$B$22 -> 0 | I217: =I214/Input01!$B$22 -> 2.1428571
A218: - Persentase peserta belum tuntas = | C218: =100-C217 -> 0 | D218: Std Deviasi = | F218: =STDEV(F13:F213) -> 8.0812204 | G218: =STDEV(G13:G213) -> 50.741626 | H218: =STDEV(H13:H213) -> 0 | I218: =STDEV(I13:I213) -> 8.0812204
A220: Mengetahui : | F220: =Input01!$B$20&", "&Input01!$B$21 -> Bantarsari, 15 Oktober 2026
A221: ="Kepala "&Input01!$B$7 -> Kepala MA Salafiyah Bantarsari | F221: Guru Mata Pelajaran
A226: =Input01!$B$18 -> H. Achmad Chuzin, S.Pd. | F226: =Input01!$B$12 -> Abdul Mu'iz
A227: ="NIP "&Input01!$B$19 -> NIP - | F227: ="NIP "&Input01!$B$13 -> NIP -

Sheet Objektif01
A2: HASIL ANALISIS SOAL PILIHAN GANDA
A4: =Input01!A7 -> Satuan Pendidikan | D4: =": "&Input01!B7 -> : MA Salafiyah Bantarsari
A5: =Input01!A10 -> Nama Tes | D5: =": "&Input01!B10 -> : Asesmen Sumatif Tengah Semester (ASTS)
A6: =Input01!A8 -> Mata Pelajaran | D6: =": "&Input01!B8 -> : Informatika
A7: =Input01!A9 -> Kelas/Program | D7: =": "&Input01!B9 -> : Fase F XI 5
A8: =Input01!A16 -> Tanggal Tes | D8: =": "&Input01!B16 -> : 23 September 2026
A9: =Input01!A11 -> Pokok Bahasan/Sub | D9: =": "&Input01!B11 -> : Bab 1, 2
A10: No Butir | B10: Daya Beda | D10: Tingkat Kesukaran | F10: Alternatif Jawaban Tidak Efektif | G10: Keterangan
B11: Koefisien | C11: Keterangan | D11: Koefisien | E11: Keterangan
A12: -1 | B12: -2 | C12: -3 | D12: -4 | E12: -5 | F12: -6 | G12: -7
A13: 1 | B13: =HLOOKUP($A13,process02!$BF$225:$DC$228,2) -> 0 | C13: =HLOOKUP($A13,process02!$BF$235:$DC$239,2) -> Tidak Baik | D13: =HLOOKUP($A13,process02!$BF$225:$DC$228,3) -> 0 | E13: =HLOOKUP($A13,process02!$BF$235:$DC$239,3) -> Sulit | F13: =HLOOKUP($A13,process02!$BF$225:$DC$228,4) -> ACE | G13: =HLOOKUP($A13,process02!$BF$235:$DC$239,5) -> Tidak Baik
A14: =A13+1 -> 2 | B14: =HLOOKUP($A14,process02!$BF$225:$DC$228,2) -> 0 | C14: =HLOOKUP($A14,process02!$BF$235:$DC$239,2) -> Tidak Baik | D14: =HLOOKUP($A14,process02!$BF$225:$DC$228,3) -> 0 | E14: =HLOOKUP($A14,process02!$BF$235:$DC$239,3) -> Sulit | F14: =HLOOKUP($A14,process02!$BF$225:$DC$228,4) -> ADE | G14: =HLOOKUP($A14,process02!$BF$235:$DC$239,5) -> Tidak Baik
A15: =A14+1 -> 3 | B15: =HLOOKUP($A15,process02!$BF$225:$DC$228,2) -> 0 | C15: =HLOOKUP($A15,process02!$BF$235:$DC$239,2) -> Tidak Baik | D15: =HLOOKUP($A15,process02!$BF$225:$DC$228,3) -> 1 | E15: =HLOOKUP($A15,process02!$BF$235:$DC$239,3) -> Mudah | F15: =HLOOKUP($A15,process02!$BF$225:$DC$228,4) -> ABDE | G15: =HLOOKUP($A15,process02!$BF$235:$DC$239,5) -> Tidak Baik
A16: =A15+1 -> 4 | B16: =HLOOKUP($A16,process02!$BF$225:$DC$228,2) -> -1 | C16: =HLOOKUP($A16,process02!$BF$235:$DC$239,2) -> Tidak Baik | D16: =HLOOKUP($A16,process02!$BF$225:$DC$228,3) -> 0.5 | E16: =HLOOKUP($A16,process02!$BF$235:$DC$239,3) -> Sedang | F16: =HLOOKUP($A16,process02!$BF$225:$DC$228,4) -> BCD | G16: =HLOOKUP($A16,process02!$BF$235:$DC$239,5) -> Tidak Baik
A17: =A16+1 -> 5 | B17: =HLOOKUP($A17,process02!$BF$225:$DC$228,2) -> 0 | C17: =HLOOKUP($A17,process02!$BF$235:$DC$239,2) -> Tidak Baik | D17: =HLOOKUP($A17,process02!$BF$225:$DC$228,3) -> 0 | E17: =HLOOKUP($A17,process02!$BF$235:$DC$239,3) -> Sulit | F17: =HLOOKUP($A17,process02!$BF$225:$DC$228,4) -> ADE | G17: =HLOOKUP($A17,process02!$BF$235:$DC$239,5) -> Tidak Baik
A18: =A17+1 -> 6 | B18: =HLOOKUP($A18,process02!$BF$225:$DC$228,2) -> 0 | C18: =HLOOKUP($A18,process02!$BF$235:$DC$239,2) -> Tidak Baik | D18: =HLOOKUP($A18,process02!$BF$225:$DC$228,3) -> 0 | E18: =HLOOKUP($A18,process02!$BF$235:$DC$239,3) -> Sulit | F18: =HLOOKUP($A18,process02!$BF$225:$DC$228,4) -> CDE | G18: =HLOOKUP($A18,process02!$BF$235:$DC$239,5) -> Tidak Baik
A19: =A18+1 -> 7 | B19: =HLOOKUP($A19,process02!$BF$225:$DC$228,2) -> 1 | C19: =HLOOKUP($A19,process02!$BF$235:$DC$239,2) -> Baik | D19: =HLOOKUP($A19,process02!$BF$225:$DC$228,3) -> 0.5 | E19: =HLOOKUP($A19,process02!$BF$235:$DC$239,3) -> Sedang | F19: =HLOOKUP($A19,process02!$BF$225:$DC$228,4) -> ACE | G19: =HLOOKUP($A19,process02!$BF$235:$DC$239,5) -> Revisi Pengecoh
A20: =A19+1 -> 8 | B20: =HLOOKUP($A20,process02!$BF$225:$DC$228,2) -> 0 | C20: =HLOOKUP($A20,process02!$BF$235:$DC$239,2) -> Tidak Baik | D20: =HLOOKUP($A20,process02!$BF$225:$DC$228,3) -> 0 | E20: =HLOOKUP($A20,process02!$BF$235:$DC$239,3) -> Sulit | F20: =HLOOKUP($A20,process02!$BF$225:$DC$228,4) -> ADE | G20: =HLOOKUP($A20,process02!$BF$235:$DC$239,5) -> Tidak Baik
A21: =A20+1 -> 9 | B21: =HLOOKUP($A21,process02!$BF$225:$DC$228,2) -> 0 | C21: =HLOOKUP($A21,process02!$BF$235:$DC$239,2) -> Tidak Baik | D21: =HLOOKUP($A21,process02!$BF$225:$DC$228,3) -> 0 | E21: =HLOOKUP($A21,process02!$BF$235:$DC$239,3) -> Sulit | F21: =HLOOKUP($A21,process02!$BF$225:$DC$228,4) -> ADE | G21: =HLOOKUP($A21,process02!$BF$235:$DC$239,5) -> Tidak Baik
A22: =A21+1 -> 10 | B22: =HLOOKUP($A22,process02!$BF$225:$DC$228,2) -> 1 | C22: =HLOOKUP($A22,process02!$BF$235:$DC$239,2) -> Baik | D22: =HLOOKUP($A22,process02!$BF$225:$DC$228,3) -> 0.5 | E22: =HLOOKUP($A22,process02!$BF$235:$DC$239,3) -> Sedang | F22: =HLOOKUP($A22,process02!$BF$225:$DC$228,4) -> ADE | G22: =HLOOKUP($A22,process02!$BF$235:$DC$239,5) -> Revisi Pengecoh
A23: =A22+1 -> 11 | B23: =HLOOKUP($A23,process02!$BF$225:$DC$228,2) -> 1 | C23: =HLOOKUP($A23,process02!$BF$235:$DC$239,2) -> Baik | D23: =HLOOKUP($A23,process02!$BF$225:$DC$228,3) -> 0.5 | E23: =HLOOKUP($A23,process02!$BF$235:$DC$239,3) -> Sedang | F23: =HLOOKUP($A23,process02!$BF$225:$DC$228,4) -> BDE | G23: =HLOOKUP($A23,process02!$BF$235:$DC$239,5) -> Revisi Pengecoh
A24: =A23+1 -> 12 | B24: =HLOOKUP($A24,process02!$BF$225:$DC$228,2) -> 0 | C24: =HLOOKUP($A24,process02!$BF$235:$DC$239,2) -> Tidak Baik | D24: =HLOOKUP($A24,process02!$BF$225:$DC$228,3) -> 0 | E24: =HLOOKUP($A24,process02!$BF$235:$DC$239,3) -> Sulit | F24: =HLOOKUP($A24,process02!$BF$225:$DC$228,4) -> ACD | G24: =HLOOKUP($A24,process02!$BF$235:$DC$239,5) -> Tidak Baik
A25: =A24+1 -> 13 | B25: =HLOOKUP($A25,process02!$BF$225:$DC$228,2) -> 0 | C25: =HLOOKUP($A25,process02!$BF$235:$DC$239,2) -> Tidak Baik | D25: =HLOOKUP($A25,process02!$BF$225:$DC$228,3) -> 0 | E25: =HLOOKUP($A25,process02!$BF$235:$DC$239,3) -> Sulit | F25: =HLOOKUP($A25,process02!$BF$225:$DC$228,4) -> ADE | G25: =HLOOKUP($A25,process02!$BF$235:$DC$239,5) -> Tidak Baik
... A61: =A60+1 -> 49 | B61: =HLOOKUP($A61,process02!$BF$225:$DC$228,2) -> - | C61: =HLOOKUP($A61,process02!$BF$235:$DC$239,2) -> - | D61: =HLOOKUP($A61,process02!$BF$225:$DC$228,3) -> - | E61: =HLOOKUP($A61,process02!$BF$235:$DC$239,3) -> - | F61: =HLOOKUP($A61,process02!$BF$225:$DC$228,4) -> - | G61: =HLOOKUP($A61,process02!$BF$235:$DC$239,5) -> -
A62: 50 | B62: =HLOOKUP($A62,process02!$BF$225:$DC$228,2) -> - | C62: =HLOOKUP($A62,process02!$BF$235:$DC$239,2) -> - | D62: =HLOOKUP($A62,process02!$BF$225:$DC$228,3) -> - | E62: =HLOOKUP($A62,process02!$BF$235:$DC$239,3) -> - | F62: =HLOOKUP($A62,process02!$BF$225:$DC$228,4) -> - | G62: =HLOOKUP($A62,process02!$BF$235:$DC$239,5) -> -
A65: Mengetahui : | F65: =Input01!$B$20&", "&Input01!$B$21 -> Bantarsari, 15 Oktober 2026
A66: ="Kepala "&Input01!$B$7 -> Kepala MA Salafiyah Bantarsari | F66: Guru Mata Pelajaran
A71: =Input01!$B$18 -> H. Achmad Chuzin, S.Pd. | F71: =Input01!$B$12 -> Abdul Mu'iz
A72: ="NIP "&Input01!$B$19 -> NIP - | F72: ="NIP "&Input01!$B$13 -> NIP -

Sheet Objektif02
A2: SEBARAN JAWABAN SOAL PILIHAN GANDA
A4: =Input01!A7 -> Satuan Pendidikan | D4: =": "&Input01!B7 -> : MA Salafiyah Bantarsari
A5: =Input01!A10 -> Nama Tes | D5: =": "&Input01!B10 -> : Asesmen Sumatif Tengah Semester (ASTS)
A6: =Input01!A8 -> Mata Pelajaran | D6: =": "&Input01!B8 -> : Informatika
A7: =Input01!A9 -> Kelas/Program | D7: =": "&Input01!B9 -> : Fase F XI 5
A8: =Input01!A16 -> Tanggal Tes | D8: =": "&Input01!B16 -> : 23 September 2026
A9: =Input01!A11 -> Pokok Bahasan/Sub | D9: =": "&Input01!B11 -> : Bab 1, 2
A10: No Butir | B10: Persentase Jawaban | H10: Jumlah
B11: A | C11: B | D11: C | E11: D | F11: E | G11: Lainnya
A12: -1 | B12: -2 | C12: -3 | D12: -4 | E12: -5 | F12: -6 | G12: -7 | H12: -8
A13: 1 | B13: =VLOOKUP(B$11,process02!$E$242:$BC$248,$A13+1) -> 0* | C13: =VLOOKUP(C$11,process02!$E$242:$BC$248,$A13+1) -> 50 | D13: =VLOOKUP(D$11,process02!$E$242:$BC$248,$A13+1) -> 0 | E13: =VLOOKUP(E$11,process02!$E$242:$BC$248,$A13+1) -> 50 | F13: =VLOOKUP(F$11,process02!$E$242:$BC$248,$A13+1) -> 0 | G13: =VLOOKUP(G$11,process02!$E$242:$BC$248,$A13+1) -> 0 | H13: =IF(B13<>"-",100,"-") -> 100
A14: =A13+1 -> 2 | B14: =VLOOKUP(B$11,process02!$E$242:$BC$248,$A14+1) -> 0 | C14: =VLOOKUP(C$11,process02!$E$242:$BC$248,$A14+1) -> 50 | D14: =VLOOKUP(D$11,process02!$E$242:$BC$248,$A14+1) -> 50 | E14: =VLOOKUP(E$11,process02!$E$242:$BC$248,$A14+1) -> 0* | F14: =VLOOKUP(F$11,process02!$E$242:$BC$248,$A14+1) -> 0 | G14: =VLOOKUP(G$11,process02!$E$242:$BC$248,$A14+1) -> 0 | H14: =IF(B14<>"-",100,"-") -> 100
A15: =A14+1 -> 3 | B15: =VLOOKUP(B$11,process02!$E$242:$BC$248,$A15+1) -> 0 | C15: =VLOOKUP(C$11,process02!$E$242:$BC$248,$A15+1) -> 0 | D15: =VLOOKUP(D$11,process02!$E$242:$BC$248,$A15+1) -> 100* | E15: =VLOOKUP(E$11,process02!$E$242:$BC$248,$A15+1) -> 0 | F15: =VLOOKUP(F$11,process02!$E$242:$BC$248,$A15+1) -> 0 | G15: =VLOOKUP(G$11,process02!$E$242:$BC$248,$A15+1) -> 0 | H15: =IF(B15<>"-",100,"-") -> 100
A16: =A15+1 -> 4 | B16: =VLOOKUP(B$11,process02!$E$242:$BC$248,$A16+1) -> 50 | C16: =VLOOKUP(C$11,process02!$E$242:$BC$248,$A16+1) -> 0 | D16: =VLOOKUP(D$11,process02!$E$242:$BC$248,$A16+1) -> 0 | E16: =VLOOKUP(E$11,process02!$E$242:$BC$248,$A16+1) -> 0 | F16: =VLOOKUP(F$11,process02!$E$242:$BC$248,$A16+1) -> 50* | G16: =VLOOKUP(G$11,process02!$E$242:$BC$248,$A16+1) -> 0 | H16: =IF(B16<>"-",100,"-") -> 100
A17: =A16+1 -> 5 | B17: =VLOOKUP(B$11,process02!$E$242:$BC$248,$A17+1) -> 0 | C17: =VLOOKUP(C$11,process02!$E$242:$BC$248,$A17+1) -> 50 | D17: =VLOOKUP(D$11,process02!$E$242:$BC$248,$A17+1) -> 50 | E17: =VLOOKUP(E$11,process02!$E$242:$BC$248,$A17+1) -> 0 | F17: =VLOOKUP(F$11,process02!$E$242:$BC$248,$A17+1) -> 0* | G17: =VLOOKUP(G$11,process02!$E$242:$BC$248,$A17+1) -> 0 | H17: =IF(B17<>"-",100,"-") -> 100
A18: =A17+1 -> 6 | B18: =VLOOKUP(B$11,process02!$E$242:$BC$248,$A18+1) -> 50 | C18: =VLOOKUP(C$11,process02!$E$242:$BC$248,$A18+1) -> 50 | D18: =VLOOKUP(D$11,process02!$E$242:$BC$248,$A18+1) -> 0* | E18: =VLOOKUP(E$11,process02!$E$242:$BC$248,$A18+1) -> 0 | F18: =VLOOKUP(F$11,process02!$E$242:$BC$248,$A18+1) -> 0 | G18: =VLOOKUP(G$11,process02!$E$242:$BC$248,$A18+1) -> 0 | H18: =IF(B18<>"-",100,"-") -> 100
A19: =A18+1 -> 7 | B19: =VLOOKUP(B$11,process02!$E$242:$BC$248,$A19+1) -> 0 | C19: =VLOOKUP(C$11,process02!$E$242:$BC$248,$A19+1) -> 50* | D19: =VLOOKUP(D$11,process02!$E$242:$BC$248,$A19+1) -> 0 | E19: =VLOOKUP(E$11,process02!$E$242:$BC$248,$A19+1) -> 50 | F19: =VLOOKUP(F$11,process02!$E$242:$BC$248,$A19+1) -> 0 | G19: =VLOOKUP(G$11,process02!$E$242:$BC$248,$A19+1) -> 0 | H19: =IF(B19<>"-",100,"-") -> 100
A20: =A19+1 -> 8 | B20: =VLOOKUP(B$11,process02!$E$242:$BC$248,$A20+1) -> 0 | C20: =VLOOKUP(C$11,process02!$E$242:$BC$248,$A20+1) -> 50 | D20: =VLOOKUP(D$11,process02!$E$242:$BC$248,$A20+1) -> 50 | E20: =VLOOKUP(E$11,process02!$E$242:$BC$248,$A20+1) -> 0* | F20: =VLOOKUP(F$11,process02!$E$242:$BC$248,$A20+1) -> 0 | G20: =VLOOKUP(G$11,process02!$E$242:$BC$248,$A20+1) -> 0 | H20: =IF(B20<>"-",100,"-") -> 100
A21: =A20+1 -> 9 | B21: =VLOOKUP(B$11,process02!$E$242:$BC$248,$A21+1) -> 0* | C21: =VLOOKUP(C$11,process02!$E$242:$BC$248,$A21+1) -> 50 | D21: =VLOOKUP(D$11,process02!$E$242:$BC$248,$A21+1) -> 50 | E21: =VLOOKUP(E$11,process02!$E$242:$BC$248,$A21+1) -> 0 | F21: =VLOOKUP(F$11,process02!$E$242:$BC$248,$A21+1) -> 0 | G21: =VLOOKUP(G$11,process02!$E$242:$BC$248,$A21+1) -> 0 | H21: =IF(B21<>"-",100,"-") -> 100
A22: =A21+1 -> 10 | B22: =VLOOKUP(B$11,process02!$E$242:$BC$248,$A22+1) -> 0 | C22: =VLOOKUP(C$11,process02!$E$242:$BC$248,$A22+1) -> 50 | D22: =VLOOKUP(D$11,process02!$E$242:$BC$248,$A22+1) -> 50* | E22: =VLOOKUP(E$11,process02!$E$242:$BC$248,$A22+1) -> 0 | F22: =VLOOKUP(F$11,process02!$E$242:$BC$248,$A22+1) -> 0 | G22: =VLOOKUP(G$11,process02!$E$242:$BC$248,$A22+1) -> 0 | H22: =IF(B22<>"-",100,"-") -> 100
